[2025-05-12T12:01:48.544+0000] {logging_mixin.py:150} INFO - Changing /opt/airflow/logs/dag_id=fpl_etl_pipeline/run_id=scheduled__2025-05-11T00:00:00+00:00/task_id=load_teams permission to 509
[2025-05-12T12:01:48.546+0000] {logging_mixin.py:150} INFO - Failed to change /opt/airflow/logs/dag_id=fpl_etl_pipeline/run_id=scheduled__2025-05-11T00:00:00+00:00/task_id=load_teams permission to 509: [Errno 1] Operation not permitted: '/opt/airflow/logs/dag_id=fpl_etl_pipeline/run_id=scheduled__2025-05-11T00:00:00+00:00/task_id=load_teams'
[2025-05-12T12:01:48.655+0000] {logging_mixin.py:150} INFO - Changing /opt/airflow/logs/dag_id=fpl_etl_pipeline/run_id=scheduled__2025-05-11T00:00:00+00:00/task_id=load_teams permission to 509
[2025-05-12T12:01:48.657+0000] {logging_mixin.py:150} INFO - Failed to change /opt/airflow/logs/dag_id=fpl_etl_pipeline/run_id=scheduled__2025-05-11T00:00:00+00:00/task_id=load_teams permission to 509: [Errno 1] Operation not permitted: '/opt/airflow/logs/dag_id=fpl_etl_pipeline/run_id=scheduled__2025-05-11T00:00:00+00:00/task_id=load_teams'
[2025-05-12T12:01:48.829+0000] {taskinstance.py:1103} INFO - Dependencies all met for dep_context=non-requeueable deps ti=<TaskInstance: fpl_etl_pipeline.load_teams scheduled__2025-05-11T00:00:00+00:00 [queued]>
[2025-05-12T12:01:48.889+0000] {taskinstance.py:1103} INFO - Dependencies all met for dep_context=requeueable deps ti=<TaskInstance: fpl_etl_pipeline.load_teams scheduled__2025-05-11T00:00:00+00:00 [queued]>
[2025-05-12T12:01:48.891+0000] {taskinstance.py:1308} INFO - Starting attempt 1 of 2
[2025-05-12T12:01:48.962+0000] {taskinstance.py:1327} INFO - Executing <Task(PythonOperator): load_teams> on 2025-05-11 00:00:00+00:00
[2025-05-12T12:01:48.980+0000] {standard_task_runner.py:57} INFO - Started process 195 to run task
[2025-05-12T12:01:48.989+0000] {standard_task_runner.py:84} INFO - Running: ['airflow', 'tasks', 'run', 'fpl_etl_pipeline', 'load_teams', 'scheduled__2025-05-11T00:00:00+00:00', '--job-id', '27', '--raw', '--subdir', 'DAGS_FOLDER/fpl_etl_pipeline.py', '--cfg-path', '/tmp/tmplfyah87v']
[2025-05-12T12:01:48.997+0000] {standard_task_runner.py:85} INFO - Job 27: Subtask load_teams
[2025-05-12T12:01:49.228+0000] {logging_mixin.py:150} INFO - Changing /opt/airflow/logs/dag_id=fpl_etl_pipeline/run_id=scheduled__2025-05-11T00:00:00+00:00/task_id=load_teams permission to 509
[2025-05-12T12:01:49.230+0000] {logging_mixin.py:150} INFO - Failed to change /opt/airflow/logs/dag_id=fpl_etl_pipeline/run_id=scheduled__2025-05-11T00:00:00+00:00/task_id=load_teams permission to 509: [Errno 1] Operation not permitted: '/opt/airflow/logs/dag_id=fpl_etl_pipeline/run_id=scheduled__2025-05-11T00:00:00+00:00/task_id=load_teams'
[2025-05-12T12:01:49.234+0000] {task_command.py:410} INFO - Running <TaskInstance: fpl_etl_pipeline.load_teams scheduled__2025-05-11T00:00:00+00:00 [running]> on host d45b3068fd3d
[2025-05-12T12:01:49.685+0000] {taskinstance.py:1547} INFO - Exporting env vars: AIRFLOW_CTX_DAG_OWNER='richardilemon' AIRFLOW_CTX_DAG_ID='fpl_etl_pipeline' AIRFLOW_CTX_TASK_ID='load_teams' AIRFLOW_CTX_EXECUTION_DATE='2025-05-11T00:00:00+00:00' AIRFLOW_CTX_TRY_NUMBER='1' AIRFLOW_CTX_DAG_RUN_ID='scheduled__2025-05-11T00:00:00+00:00'
[2025-05-12T12:01:49.689+0000] {logging_mixin.py:150} INFO - Creating teams table...
[2025-05-12T12:01:49.693+0000] {logging_mixin.py:150} INFO - Fetching teams for 2016-17...
[2025-05-12T12:02:22.542+0000] {logging_mixin.py:150} INFO - ⚠️ Failed to fetch teams.csv for 2016-17: 404 Client Error: Not Found for url: https://raw.githubusercontent.com/vaastav/Fantasy-Premier-League/master/data/2016-17/teams.csv
[2025-05-12T12:02:22.575+0000] {logging_mixin.py:150} INFO - ⚠️ Skipping 2016-17: No CSV data.
[2025-05-12T12:02:22.584+0000] {logging_mixin.py:150} INFO - Fetching teams for 2017-18...
[2025-05-12T12:03:27.407+0000] {logging_mixin.py:150} INFO - ⚠️ Failed to fetch teams.csv for 2017-18: ('Connection aborted.', OSError(0, 'Error'))
[2025-05-12T12:03:27.410+0000] {logging_mixin.py:150} INFO - ⚠️ Skipping 2017-18: No CSV data.
[2025-05-12T12:03:27.411+0000] {logging_mixin.py:150} INFO - Fetching teams for 2018-19...
[2025-05-12T12:03:40.797+0000] {logging_mixin.py:150} INFO - ⚠️ Failed to fetch teams.csv for 2018-19: 404 Client Error: Not Found for url: https://raw.githubusercontent.com/vaastav/Fantasy-Premier-League/master/data/2018-19/teams.csv
[2025-05-12T12:03:40.818+0000] {logging_mixin.py:150} INFO - ⚠️ Skipping 2018-19: No CSV data.
[2025-05-12T12:03:40.825+0000] {logging_mixin.py:150} INFO - Fetching teams for 2019-20...
[2025-05-12T12:04:25.711+0000] {logging_mixin.py:150} INFO - ✅ Loaded teams for 2019-20
[2025-05-12T12:04:25.713+0000] {logging_mixin.py:150} INFO - Fetching teams for 2020-21...
[2025-05-12T12:05:07.052+0000] {logging_mixin.py:150} INFO - ✅ Loaded teams for 2020-21
[2025-05-12T12:05:07.053+0000] {logging_mixin.py:150} INFO - Fetching teams for 2021-22...
[2025-05-12T12:05:24.022+0000] {logging_mixin.py:150} INFO - ✅ Loaded teams for 2021-22
[2025-05-12T12:05:24.026+0000] {logging_mixin.py:150} INFO - Fetching teams for 2022-23...
[2025-05-12T12:05:40.538+0000] {logging_mixin.py:150} INFO - ✅ Loaded teams for 2022-23
[2025-05-12T12:05:40.541+0000] {logging_mixin.py:150} INFO - Fetching teams for 2023-24...
[2025-05-12T12:05:44.551+0000] {logging_mixin.py:150} INFO - ⚠️ Failed to fetch teams.csv for 2023-24: HTTPSConnectionPool(host='raw.githubusercontent.com', port=443): Max retries exceeded with url: /vaastav/Fantasy-Premier-League/master/data/2023-24/teams.csv (Caused by NewConnectionError('<urllib3.connection.HTTPSConnection object at 0x7f3e406985d0>: Failed to establish a new connection: [Errno 101] Network is unreachable'))
[2025-05-12T12:05:44.552+0000] {logging_mixin.py:150} INFO - ⚠️ Skipping 2023-24: No CSV data.
[2025-05-12T12:05:44.552+0000] {logging_mixin.py:150} INFO - Fetching teams for 2024-25...
[2025-05-12T12:05:48.560+0000] {logging_mixin.py:150} INFO - ⚠️ Failed to fetch teams.csv for 2024-25: HTTPSConnectionPool(host='raw.githubusercontent.com', port=443): Max retries exceeded with url: /vaastav/Fantasy-Premier-League/master/data/2024-25/teams.csv (Caused by NewConnectionError('<urllib3.connection.HTTPSConnection object at 0x7f3e40698690>: Failed to establish a new connection: [Errno 101] Network is unreachable'))
[2025-05-12T12:05:48.561+0000] {logging_mixin.py:150} INFO - ⚠️ Skipping 2024-25: No CSV data.
[2025-05-12T12:05:48.562+0000] {logging_mixin.py:150} INFO - ✅ Teams history loaded successfully.
[2025-05-12T12:05:48.581+0000] {logging_mixin.py:150} INFO - Creating teams table...
[2025-05-12T12:05:48.584+0000] {logging_mixin.py:150} INFO - Fetching teams data...
[2025-05-12T12:06:20.928+0000] {taskinstance.py:1824} ERROR - Task failed with exception
Traceback (most recent call last):
  File "/home/airflow/.local/lib/python3.7/site-packages/urllib3/connectionpool.py", line 721, in urlopen
    chunked=chunked,
  File "/home/airflow/.local/lib/python3.7/site-packages/urllib3/connectionpool.py", line 403, in _make_request
    self._validate_conn(conn)
  File "/home/airflow/.local/lib/python3.7/site-packages/urllib3/connectionpool.py", line 1053, in _validate_conn
    conn.connect()
  File "/home/airflow/.local/lib/python3.7/site-packages/urllib3/connection.py", line 429, in connect
    tls_in_tls=tls_in_tls,
  File "/home/airflow/.local/lib/python3.7/site-packages/urllib3/util/ssl_.py", line 450, in ssl_wrap_socket
    sock, context, tls_in_tls, server_hostname=server_hostname
  File "/home/airflow/.local/lib/python3.7/site-packages/urllib3/util/ssl_.py", line 493, in _ssl_wrap_socket_impl
    return ssl_context.wrap_socket(sock, server_hostname=server_hostname)
  File "/usr/local/lib/python3.7/ssl.py", line 423, in wrap_socket
    session=session
  File "/usr/local/lib/python3.7/ssl.py", line 870, in _create
    self.do_handshake()
  File "/usr/local/lib/python3.7/ssl.py", line 1139, in do_handshake
    self._sslobj.do_handshake()
OSError: [Errno 0] Error

During handling of the above exception, another exception occurred:

Traceback (most recent call last):
  File "/home/airflow/.local/lib/python3.7/site-packages/requests/adapters.py", line 497, in send
    chunked=chunked,
  File "/home/airflow/.local/lib/python3.7/site-packages/urllib3/connectionpool.py", line 799, in urlopen
    method, url, error=e, _pool=self, _stacktrace=sys.exc_info()[2]
  File "/home/airflow/.local/lib/python3.7/site-packages/urllib3/util/retry.py", line 550, in increment
    raise six.reraise(type(error), error, _stacktrace)
  File "/home/airflow/.local/lib/python3.7/site-packages/urllib3/packages/six.py", line 769, in reraise
    raise value.with_traceback(tb)
  File "/home/airflow/.local/lib/python3.7/site-packages/urllib3/connectionpool.py", line 721, in urlopen
    chunked=chunked,
  File "/home/airflow/.local/lib/python3.7/site-packages/urllib3/connectionpool.py", line 403, in _make_request
    self._validate_conn(conn)
  File "/home/airflow/.local/lib/python3.7/site-packages/urllib3/connectionpool.py", line 1053, in _validate_conn
    conn.connect()
  File "/home/airflow/.local/lib/python3.7/site-packages/urllib3/connection.py", line 429, in connect
    tls_in_tls=tls_in_tls,
  File "/home/airflow/.local/lib/python3.7/site-packages/urllib3/util/ssl_.py", line 450, in ssl_wrap_socket
    sock, context, tls_in_tls, server_hostname=server_hostname
  File "/home/airflow/.local/lib/python3.7/site-packages/urllib3/util/ssl_.py", line 493, in _ssl_wrap_socket_impl
    return ssl_context.wrap_socket(sock, server_hostname=server_hostname)
  File "/usr/local/lib/python3.7/ssl.py", line 423, in wrap_socket
    session=session
  File "/usr/local/lib/python3.7/ssl.py", line 870, in _create
    self.do_handshake()
  File "/usr/local/lib/python3.7/ssl.py", line 1139, in do_handshake
    self._sslobj.do_handshake()
urllib3.exceptions.ProtocolError: ('Connection aborted.', OSError(0, 'Error'))

During handling of the above exception, another exception occurred:

Traceback (most recent call last):
  File "/home/airflow/.local/lib/python3.7/site-packages/airflow/operators/python.py", line 181, in execute
    return_value = self.execute_callable()
  File "/home/airflow/.local/lib/python3.7/site-packages/airflow/operators/python.py", line 198, in execute_callable
    return self.python_callable(*self.op_args, **self.op_kwargs)
  File "/opt/airflow/dags/fpl_etl_pipeline.py", line 20, in load_teams_task
    load_teams_live_main()  # No season parameter needed (uses default)
  File "/app/load_teams_live.py", line 91, in main
    teams = fetch_teams_data()
  File "/app/load_teams_live.py", line 9, in fetch_teams_data
    response = requests.get(url)
  File "/home/airflow/.local/lib/python3.7/site-packages/requests/api.py", line 73, in get
    return request("get", url, params=params, **kwargs)
  File "/home/airflow/.local/lib/python3.7/site-packages/requests/api.py", line 59, in request
    return session.request(method=method, url=url, **kwargs)
  File "/home/airflow/.local/lib/python3.7/site-packages/requests/sessions.py", line 589, in request
    resp = self.send(prep, **send_kwargs)
  File "/home/airflow/.local/lib/python3.7/site-packages/requests/sessions.py", line 703, in send
    r = adapter.send(request, **kwargs)
  File "/home/airflow/.local/lib/python3.7/site-packages/requests/adapters.py", line 501, in send
    raise ConnectionError(err, request=request)
requests.exceptions.ConnectionError: ('Connection aborted.', OSError(0, 'Error'))
[2025-05-12T12:06:20.982+0000] {taskinstance.py:1350} INFO - Marking task as UP_FOR_RETRY. dag_id=fpl_etl_pipeline, task_id=load_teams, execution_date=20250511T000000, start_date=20250512T120148, end_date=20250512T120620
[2025-05-12T12:06:21.020+0000] {standard_task_runner.py:109} ERROR - Failed to execute job 27 for task load_teams (('Connection aborted.', OSError(0, 'Error')); 195)
[2025-05-12T12:06:21.059+0000] {local_task_job_runner.py:225} INFO - Task exited with return code 1
[2025-05-12T12:06:21.119+0000] {taskinstance.py:2653} INFO - 0 downstream tasks scheduled from follow-on schedule check
