[2025-05-09T12:49:31.441+0000] {logging_mixin.py:150} INFO - Changing /opt/airflow/logs/dag_id=fpl_etl_pipeline/run_id=scheduled__2025-05-08T00:00:00+00:00/task_id=load_gameweeks permission to 509
[2025-05-09T12:49:31.443+0000] {logging_mixin.py:150} INFO - Failed to change /opt/airflow/logs/dag_id=fpl_etl_pipeline/run_id=scheduled__2025-05-08T00:00:00+00:00/task_id=load_gameweeks permission to 509: [Errno 1] Operation not permitted: '/opt/airflow/logs/dag_id=fpl_etl_pipeline/run_id=scheduled__2025-05-08T00:00:00+00:00/task_id=load_gameweeks'
[2025-05-09T12:49:31.537+0000] {logging_mixin.py:150} INFO - Changing /opt/airflow/logs/dag_id=fpl_etl_pipeline/run_id=scheduled__2025-05-08T00:00:00+00:00/task_id=load_gameweeks permission to 509
[2025-05-09T12:49:31.540+0000] {logging_mixin.py:150} INFO - Failed to change /opt/airflow/logs/dag_id=fpl_etl_pipeline/run_id=scheduled__2025-05-08T00:00:00+00:00/task_id=load_gameweeks permission to 509: [Errno 1] Operation not permitted: '/opt/airflow/logs/dag_id=fpl_etl_pipeline/run_id=scheduled__2025-05-08T00:00:00+00:00/task_id=load_gameweeks'
[2025-05-09T12:49:32.016+0000] {taskinstance.py:1103} INFO - Dependencies all met for dep_context=non-requeueable deps ti=<TaskInstance: fpl_etl_pipeline.load_gameweeks scheduled__2025-05-08T00:00:00+00:00 [queued]>
[2025-05-09T12:49:32.040+0000] {taskinstance.py:1103} INFO - Dependencies all met for dep_context=requeueable deps ti=<TaskInstance: fpl_etl_pipeline.load_gameweeks scheduled__2025-05-08T00:00:00+00:00 [queued]>
[2025-05-09T12:49:32.041+0000] {taskinstance.py:1308} INFO - Starting attempt 1 of 2
[2025-05-09T12:49:32.074+0000] {taskinstance.py:1327} INFO - Executing <Task(PythonOperator): load_gameweeks> on 2025-05-08 00:00:00+00:00
[2025-05-09T12:49:32.084+0000] {standard_task_runner.py:57} INFO - Started process 562 to run task
[2025-05-09T12:49:32.092+0000] {standard_task_runner.py:84} INFO - Running: ['airflow', 'tasks', 'run', 'fpl_etl_pipeline', 'load_gameweeks', 'scheduled__2025-05-08T00:00:00+00:00', '--job-id', '22', '--raw', '--subdir', 'DAGS_FOLDER/fpl_etl_pipeline.py', '--cfg-path', '/tmp/tmp0_rcrcxq']
[2025-05-09T12:49:32.098+0000] {standard_task_runner.py:85} INFO - Job 22: Subtask load_gameweeks
[2025-05-09T12:49:32.403+0000] {logging_mixin.py:150} INFO - Changing /opt/airflow/logs/dag_id=fpl_etl_pipeline/run_id=scheduled__2025-05-08T00:00:00+00:00/task_id=load_gameweeks permission to 509
[2025-05-09T12:49:32.406+0000] {logging_mixin.py:150} INFO - Failed to change /opt/airflow/logs/dag_id=fpl_etl_pipeline/run_id=scheduled__2025-05-08T00:00:00+00:00/task_id=load_gameweeks permission to 509: [Errno 1] Operation not permitted: '/opt/airflow/logs/dag_id=fpl_etl_pipeline/run_id=scheduled__2025-05-08T00:00:00+00:00/task_id=load_gameweeks'
[2025-05-09T12:49:32.418+0000] {task_command.py:410} INFO - Running <TaskInstance: fpl_etl_pipeline.load_gameweeks scheduled__2025-05-08T00:00:00+00:00 [running]> on host 15039a0aaf98
[2025-05-09T12:49:33.034+0000] {taskinstance.py:1547} INFO - Exporting env vars: AIRFLOW_CTX_DAG_OWNER='richardilemon' AIRFLOW_CTX_DAG_ID='fpl_etl_pipeline' AIRFLOW_CTX_TASK_ID='load_gameweeks' AIRFLOW_CTX_EXECUTION_DATE='2025-05-08T00:00:00+00:00' AIRFLOW_CTX_TRY_NUMBER='1' AIRFLOW_CTX_DAG_RUN_ID='scheduled__2025-05-08T00:00:00+00:00'
[2025-05-09T12:49:33.041+0000] {logging_mixin.py:150} INFO - Creating game_weeks table...
[2025-05-09T12:49:33.119+0000] {logging_mixin.py:150} INFO - Processing season 2020-21...
[2025-05-09T12:50:29.780+0000] {taskinstance.py:1824} ERROR - Task failed with exception
Traceback (most recent call last):
  File "/home/airflow/.local/lib/python3.7/site-packages/urllib3/connectionpool.py", line 721, in urlopen
    chunked=chunked,
  File "/home/airflow/.local/lib/python3.7/site-packages/urllib3/connectionpool.py", line 403, in _make_request
    self._validate_conn(conn)
  File "/home/airflow/.local/lib/python3.7/site-packages/urllib3/connectionpool.py", line 1053, in _validate_conn
    conn.connect()
  File "/home/airflow/.local/lib/python3.7/site-packages/urllib3/connection.py", line 429, in connect
    tls_in_tls=tls_in_tls,
  File "/home/airflow/.local/lib/python3.7/site-packages/urllib3/util/ssl_.py", line 450, in ssl_wrap_socket
    sock, context, tls_in_tls, server_hostname=server_hostname
  File "/home/airflow/.local/lib/python3.7/site-packages/urllib3/util/ssl_.py", line 493, in _ssl_wrap_socket_impl
    return ssl_context.wrap_socket(sock, server_hostname=server_hostname)
  File "/usr/local/lib/python3.7/ssl.py", line 423, in wrap_socket
    session=session
  File "/usr/local/lib/python3.7/ssl.py", line 870, in _create
    self.do_handshake()
  File "/usr/local/lib/python3.7/ssl.py", line 1139, in do_handshake
    self._sslobj.do_handshake()
OSError: [Errno 0] Error

During handling of the above exception, another exception occurred:

Traceback (most recent call last):
  File "/home/airflow/.local/lib/python3.7/site-packages/requests/adapters.py", line 497, in send
    chunked=chunked,
  File "/home/airflow/.local/lib/python3.7/site-packages/urllib3/connectionpool.py", line 799, in urlopen
    method, url, error=e, _pool=self, _stacktrace=sys.exc_info()[2]
  File "/home/airflow/.local/lib/python3.7/site-packages/urllib3/util/retry.py", line 550, in increment
    raise six.reraise(type(error), error, _stacktrace)
  File "/home/airflow/.local/lib/python3.7/site-packages/urllib3/packages/six.py", line 769, in reraise
    raise value.with_traceback(tb)
  File "/home/airflow/.local/lib/python3.7/site-packages/urllib3/connectionpool.py", line 721, in urlopen
    chunked=chunked,
  File "/home/airflow/.local/lib/python3.7/site-packages/urllib3/connectionpool.py", line 403, in _make_request
    self._validate_conn(conn)
  File "/home/airflow/.local/lib/python3.7/site-packages/urllib3/connectionpool.py", line 1053, in _validate_conn
    conn.connect()
  File "/home/airflow/.local/lib/python3.7/site-packages/urllib3/connection.py", line 429, in connect
    tls_in_tls=tls_in_tls,
  File "/home/airflow/.local/lib/python3.7/site-packages/urllib3/util/ssl_.py", line 450, in ssl_wrap_socket
    sock, context, tls_in_tls, server_hostname=server_hostname
  File "/home/airflow/.local/lib/python3.7/site-packages/urllib3/util/ssl_.py", line 493, in _ssl_wrap_socket_impl
    return ssl_context.wrap_socket(sock, server_hostname=server_hostname)
  File "/usr/local/lib/python3.7/ssl.py", line 423, in wrap_socket
    session=session
  File "/usr/local/lib/python3.7/ssl.py", line 870, in _create
    self.do_handshake()
  File "/usr/local/lib/python3.7/ssl.py", line 1139, in do_handshake
    self._sslobj.do_handshake()
urllib3.exceptions.ProtocolError: ('Connection aborted.', OSError(0, 'Error'))

During handling of the above exception, another exception occurred:

Traceback (most recent call last):
  File "/home/airflow/.local/lib/python3.7/site-packages/airflow/operators/python.py", line 181, in execute
    return_value = self.execute_callable()
  File "/home/airflow/.local/lib/python3.7/site-packages/airflow/operators/python.py", line 198, in execute_callable
    return self.python_callable(*self.op_args, **self.op_kwargs)
  File "/app/load_gameweeks.py", line 75, in main
    csv_text = fetch_fixtures_for_season(season)
  File "/app/load_gameweeks.py", line 13, in fetch_fixtures_for_season
    response = requests.get(url)
  File "/home/airflow/.local/lib/python3.7/site-packages/requests/api.py", line 73, in get
    return request("get", url, params=params, **kwargs)
  File "/home/airflow/.local/lib/python3.7/site-packages/requests/api.py", line 59, in request
    return session.request(method=method, url=url, **kwargs)
  File "/home/airflow/.local/lib/python3.7/site-packages/requests/sessions.py", line 589, in request
    resp = self.send(prep, **send_kwargs)
  File "/home/airflow/.local/lib/python3.7/site-packages/requests/sessions.py", line 703, in send
    r = adapter.send(request, **kwargs)
  File "/home/airflow/.local/lib/python3.7/site-packages/requests/adapters.py", line 501, in send
    raise ConnectionError(err, request=request)
requests.exceptions.ConnectionError: ('Connection aborted.', OSError(0, 'Error'))
[2025-05-09T12:50:29.925+0000] {taskinstance.py:1350} INFO - Marking task as UP_FOR_RETRY. dag_id=fpl_etl_pipeline, task_id=load_gameweeks, execution_date=20250508T000000, start_date=20250509T124932, end_date=20250509T125029
[2025-05-09T12:50:30.025+0000] {standard_task_runner.py:109} ERROR - Failed to execute job 22 for task load_gameweeks (('Connection aborted.', OSError(0, 'Error')); 562)
[2025-05-09T12:50:30.117+0000] {local_task_job_runner.py:225} INFO - Task exited with return code 1
[2025-05-09T12:50:30.324+0000] {taskinstance.py:2653} INFO - 0 downstream tasks scheduled from follow-on schedule check
